<mujoco model="dust">
	<include file="./common/visual.xml" />
	<include file="./common/materials.xml" />
	<asset>
		<texture builtin="gradient" height="800" mark="random" markrgb="1 1 1" name="skybox" rgb1=".4 .6 .8" rgb2="0 0 0" type="skybox" width="800" />
	</asset>
	<option timestep="0.004" />
	<default>
		<motor ctrllimited="true" ctrlrange="-1 1" />
		<general ctrllimited="true" />
		<default class="dust">
			<joint armature=".01" damping=".2" range="-60 60" solimplimit="0 .99 .01" stiffness=".6" type="hinge" />
			<geom friction=".7" solimp=".95 .99 .003" solref=".015 1" />
		</default>
	</default>
	<worldbody>
		<camera mode="trackcom" name="tracking_top" pos="0 0 4" xyaxes="1 0 0 0 1 0" />
		<geom material="grid" name="ground" size=".5 .5 .1" type="plane" />
		<body childclass="dust" name="root" pos="0 0 0.8">
			<light diffuse=".6 .6 .6" dir="0 0 -1" mode="track" name="light" pos="0 0 0.5" specular=".3 .3 .3" />
			<joint damping="0" limited="false" name="root" type="free" />
			<geom name="root" size="0.025 0.025 0.025" type="box" />
			<body name="3" pos="0.0 0.0 0.0" quat="-0.5234913841085711 0.7902578683106048 0.28128732084231806 -0.1494212684681198">
				<joint axis="1 0 0" name="3_x" range="-7.827448645876974 7.827448645876974" />
				<joint axis="0 1 0" name="3_y" range="-7.827448645876974 7.827448645876974" />
				<joint axis="0 0 1" name="3_z" range="-7.827448645876974 7.827448645876974" />
				<geom name="3" pos="0.13947276988238744 0.0 0.0" size="0.13947276988238744 0.04258753045254567 0.04258753045254567" type="ellipsoid" />
				<body name="2" pos="0.2789455397647749 0.0 0.0" quat="0.5398115174916923 -0.669065941637827 0.1521647226645651 -0.48764760688433634">
					<joint axis="1 0 0" name="2_x" range="-132.4283365973835 132.4283365973835" />
					<joint axis="0 1 0" name="2_y" range="-132.4283365973835 132.4283365973835" />
					<joint axis="0 0 1" name="2_z" range="-132.4283365973835 132.4283365973835" />
					<geom name="2" pos="0.08557368314490302 0.0 0.0" size="0.08557368314490302 0.023738892838671945 0.023738892838671945" type="ellipsoid" />
				</body>
				<body name="1" pos="0.2789455397647749 0.0 0.0" quat="0.42850073128283483 -0.757374020531164 0.42805014571751765 -0.2440180097159791">
					<joint axis="1 0 0" name="1_x" range="-123.06697263005813 123.06697263005813" />
					<joint axis="0 1 0" name="1_y" range="-123.06697263005813 123.06697263005813" />
					<joint axis="0 0 1" name="1_z" range="-123.06697263005813 123.06697263005813" />
					<geom name="1" pos="0.10650255536341147 0.0 0.0" size="0.10650255536341147 0.022721122539307623 0.022721122539307623" type="ellipsoid" />
					<body name="0" pos="0.21300511072682293 0.0 0.0" quat="-0.04227718964160315 -0.027585612556598804 0.8119490864056469 0.5815413607826363">
						<joint axis="1 0 0" name="0_x" range="-122.22214031125333 122.22214031125333" />
						<joint axis="0 1 0" name="0_y" range="-122.22214031125333 122.22214031125333" />
						<joint axis="0 0 1" name="0_z" range="-122.22214031125333 122.22214031125333" />
						<geom name="0" pos="0.08741068491238566 0.0 0.0" size="0.08741068491238566 0.0147086741462358 0.0147086741462358" type="ellipsoid" />
					</body>
				</body>
			</body>
		</body>
	</worldbody>
	<contact>
		<exclude body1="3" body2="2" />
		<exclude body1="1" body2="0" />
		<exclude body1="root" body2="0" />
		<exclude body1="root" body2="2" />
		<exclude body1="root" body2="1" />
		<exclude body1="3" body2="1" />
		<exclude body1="root" body2="3" />
	</contact>
	<actuator>
		<motor gear="2" joint="1_z" name="1_z" />
		<motor gear="2" joint="0_x" name="0_x" />
		<motor gear="2" joint="3_x" name="3_x" />
		<motor gear="2" joint="2_y" name="2_y" />
		<motor gear="2" joint="2_x" name="2_x" />
		<motor gear="2" joint="0_z" name="0_z" />
		<motor gear="2" joint="3_y" name="3_y" />
		<motor gear="2" joint="2_z" name="2_z" />
		<motor gear="2" joint="1_x" name="1_x" />
		<motor gear="2" joint="0_y" name="0_y" />
		<motor gear="2" joint="1_y" name="1_y" />
		<motor gear="2" joint="3_z" name="3_z" />
	</actuator>
</mujoco>