<mujoco model="starfish">
    <compiler inertiafromgeom="true" angle="degree"/>
	<include file="./common/visual.xml" />
	<include file="./common/materials.xml" />
	<asset>
		<texture builtin="gradient" height="800" mark="random" markrgb="1 1 1" name="skybox" rgb1=".4 .6 .8" rgb2="0 0 0" type="skybox" width="800" />
	</asset>
	<!--Viscosity:: water:0.000894, air:0.00001983 -->
	<!--Density:: water:1000, air:1.2 -->
	<option gravity="0 0 -0.1" timestep="0.04" viscosity="0.1" density="4000" />
	<default>
		<motor ctrllimited="true" ctrlrange="-1 1" />
		<general ctrllimited="true" />
		<default class="starfish">
			<joint armature=".01" damping=".2" range="-30.5 30.5" solimplimit="0 .99 .01" stiffness=".6" type="hinge" />
			<geom friction=".7" solimp=".95 .99 .003" solref=".015 1" />
		</default>
	</default>
	<worldbody>
		<camera mode="trackcom" target="agent0/root" name="tracking_top" pos="0 -2 2" euler="50.0 0.0 0.0" />
		<!--camera mode="fixed" name="arm_eye" pos="0 -2 2" euler="50.0 0.0 0.0" /-->
		<geom material="grid" name="ground" size="3 3 1" type="plane" />

        <body childclass="starfish" name="agent0/root" pos="0 0 1.0">
          <joint damping="0" limited="false" name="agent0/root/free" type="free"/>
          <geom name="agent0/root" rgba="1 0 0 1" size="0.05" type="sphere"/>
          <body euler="0.0 90.0 90.0" name="agent0/left_arm" pos="0.15 0.0 0.0">
            <joint axis="1 0 0" name="agent0/left_arm_x"/>
            <joint axis="0 1 0" name="agent0/left_arm_y"/>
            <joint axis="0 0 1" name="agent0/left_arm_z"/>
            <geom name="agent0/left_arm" rgba="0.9333333333333333 0.8313725490196079 0.9411764705882353 1.0" size="0.04 0.01 0.08" type="box"/>
            <body euler="0.0 0.0 0.0" name="agent0/left_arm/tip" pos="0.0 0.0 0.15">
              <joint axis="1 0 0" name="agent0/left_arm/tip_x"/>
              <joint axis="0 1 0" name="agent0/left_arm/tip_y"/>
              <joint axis="0 0 1" name="agent0/left_arm/tip_z"/>
              <geom name="agent0/left_arm/tip" rgba="0.3843137254901961 0.14901960784313725 0.8549019607843137 1.0" size="0.03 0.01 0.08" type="box"/>
            </body>
          </body>
          <body euler="0.0 -90.0 90.0" name="agent0/right_arm" pos="-0.15 0.0 0.0">
            <joint axis="1 0 0" name="agent0/right_arm_x"/>
            <joint axis="0 1 0" name="agent0/right_arm_y"/>
            <joint axis="0 0 1" name="agent0/right_arm_z"/>
            <geom name="agent0/right_arm" rgba="0.9333333333333333 0.8313725490196079 0.9411764705882353 1.0" size="0.04 0.01 0.08" type="box"/>
            <body euler="0.0 0.0 0.0" name="agent0/right_arm/tip" pos="0.0 0.0 0.15">
              <joint axis="1 0 0" name="agent0/right_arm/tip_x"/>
              <joint axis="0 1 0" name="agent0/right_arm/tip_y"/>
              <joint axis="0 0 1" name="agent0/right_arm/tip_z"/>
              <geom name="agent0/right_arm/tip" rgba="0.3843137254901961 0.14901960784313725 0.8549019607843137 1.0" size="0.03 0.01 0.08" type="box"/>
            </body>
          </body>
          <body euler="-90.0 0.0 0.0" name="agent0/front_arm" pos="0.0 0.15 0.0">
            <joint axis="1 0 0" name="agent0/front_arm_x"/>
            <joint axis="0 1 0" name="agent0/front_arm_y"/>
            <joint axis="0 0 1" name="agent0/front_arm_z"/>
            <geom name="agent0/front_arm" rgba="0.9333333333333333 0.8313725490196079 0.9411764705882353 1.0" size="0.04 0.01 0.08" type="box"/>
            <body euler="0.0 0.0 0.0" name="agent0/front_arm/tip" pos="0.0 0.0 0.15">
              <joint axis="1 0 0" name="agent0/front_arm/tip_x"/>
              <joint axis="0 1 0" name="agent0/front_arm/tip_y"/>
              <joint axis="0 0 1" name="agent0/front_arm/tip_z"/>
              <geom name="agent0/front_arm/tip" rgba="0.3843137254901961 0.14901960784313725 0.8549019607843137 1.0" size="0.03 0.01 0.08" type="box"/>
              <camera euler="180.0 0.0 0.0" mode="fixed" name="arm_eye" pos="0 0 0.08"/>
            </body>
          </body>
          <body euler="90.0 0.0 0.0" name="agent0/back_arm" pos="0.0 -0.15 0.0">
            <joint axis="1 0 0" name="agent0/back_arm_x"/>
            <joint axis="0 1 0" name="agent0/back_arm_y"/>
            <joint axis="0 0 1" name="agent0/back_arm_z"/>
            <geom name="agent0/back_arm" rgba="0.9333333333333333 0.8313725490196079 0.9411764705882353 1.0" size="0.04 0.01 0.08" type="box"/>
            <body euler="0.0 0.0 0.0" name="agent0/back_arm/tip" pos="0.0 0.0 0.15">
              <joint axis="1 0 0" name="agent0/back_arm/tip_x"/>
              <joint axis="0 1 0" name="agent0/back_arm/tip_y"/>
              <joint axis="0 0 1" name="agent0/back_arm/tip_z"/>
              <geom name="agent0/back_arm/tip" rgba="0.3843137254901961 0.14901960784313725 0.8549019607843137 1.0" size="0.03 0.01 0.08" type="box"/>
            </body>
          </body>
        </body>


    <body name="target" pos="-0.5025618217921284 -0.30252641539177194 0.009889796273572816">
			<geom material="target" name="target" pos="0 0 0" size="0.02 0.02 0.02" type="box" />
		</body>
	</worldbody>
<contact>
  <exclude body1="agent0/root" body2="agent0/left_arm"/>
  <exclude body1="agent0/left_arm" body2="agent0/left_arm/tip"/>
  <exclude body1="agent0/root" body2="agent0/right_arm"/>
  <exclude body1="agent0/right_arm" body2="agent0/right_arm/tip"/>
  <exclude body1="agent0/root" body2="agent0/front_arm"/>
  <exclude body1="agent0/front_arm" body2="agent0/front_arm/tip"/>
  <exclude body1="agent0/root" body2="agent0/back_arm"/>
  <exclude body1="agent0/back_arm" body2="agent0/back_arm/tip"/>
</contact>
<actuator>
  <motor gear="1" joint="agent0/left_arm_x" name="agent0/left_arm_x"/>
  <motor gear="1" joint="agent0/left_arm_y" name="agent0/left_arm_y"/>
  <motor gear="1" joint="agent0/left_arm_z" name="agent0/left_arm_z"/>
  <motor gear="1" joint="agent0/left_arm/tip_x" name="agent0/left_arm/tip_x"/>
  <motor gear="1" joint="agent0/left_arm/tip_y" name="agent0/left_arm/tip_y"/>
  <motor gear="1" joint="agent0/left_arm/tip_z" name="agent0/left_arm/tip_z"/>
  <motor gear="1" joint="agent0/right_arm_x" name="agent0/right_arm_x"/>
  <motor gear="1" joint="agent0/right_arm_y" name="agent0/right_arm_y"/>
  <motor gear="1" joint="agent0/right_arm_z" name="agent0/right_arm_z"/>
  <motor gear="1" joint="agent0/right_arm/tip_x" name="agent0/right_arm/tip_x"/>
  <motor gear="1" joint="agent0/right_arm/tip_y" name="agent0/right_arm/tip_y"/>
  <motor gear="1" joint="agent0/right_arm/tip_z" name="agent0/right_arm/tip_z"/>
  <motor gear="1" joint="agent0/front_arm_x" name="agent0/front_arm_x"/>
  <motor gear="1" joint="agent0/front_arm_y" name="agent0/front_arm_y"/>
  <motor gear="1" joint="agent0/front_arm_z" name="agent0/front_arm_z"/>
  <motor gear="1" joint="agent0/front_arm/tip_x" name="agent0/front_arm/tip_x"/>
  <motor gear="1" joint="agent0/front_arm/tip_y" name="agent0/front_arm/tip_y"/>
  <motor gear="1" joint="agent0/front_arm/tip_z" name="agent0/front_arm/tip_z"/>
  <motor gear="1" joint="agent0/back_arm_x" name="agent0/back_arm_x"/>
  <motor gear="1" joint="agent0/back_arm_y" name="agent0/back_arm_y"/>
  <motor gear="1" joint="agent0/back_arm_z" name="agent0/back_arm_z"/>
  <motor gear="1" joint="agent0/back_arm/tip_x" name="agent0/back_arm/tip_x"/>
  <motor gear="1" joint="agent0/back_arm/tip_y" name="agent0/back_arm/tip_y"/>
  <motor gear="1" joint="agent0/back_arm/tip_z" name="agent0/back_arm/tip_z"/>
</actuator>
</mujoco>