<mujoco model="wobble">
	<include file="./common/visual.xml"/>
  <include file="./common/materials.xml"/>
  <asset>
      <texture name="skybox" type="skybox" builtin="gradient" rgb1=".4 .6 .8" rgb2="0 0 0" width="800" height="800" mark="random" markrgb="1 1 1"/>
  </asset>

  <option timestep="0.004" density="5000">
    <flag gravity="disable" constraint="disable"/>
  </option>

  <default>
    <general ctrllimited="true"/>
    <default class="wobble">
      <joint type="hinge" limited="false" range="-90 90" damping="2e-5" solreflimit=".1 1" solimplimit="0 .8 .1"/>
      <geom material="self"/>
    </default>
  </default>

  <worldbody>
    <camera name="tracking_top" pos="0 0 0.45" xyaxes="1 0 0 0 1 0" mode="trackcom"/>
    <camera name="tracking_x" pos="-.3 0 .2" xyaxes="0 -1 0 0.342 0 0.940" fovy="60" mode="trackcom"/>
    <camera name="tracking_y" pos="0 -.3 .2" xyaxes="1 0 0 0 0.342 0.940" fovy="60" mode="trackcom"/>
    <camera name="fixed_top" pos="0 0 5.5" fovy="10"/>
    <geom name="ground" type="plane" size=".5 .5 .1" material="grid"/>
    <geom name="target" type="sphere" pos="0 .4 .1" size=".04" material="target"/>

    <body name="trunk" pos="0 0 0.1" childclass="wobble">
    	<light name="light" diffuse=".6 .6 .6" pos="0 0 0.5" dir="0 0 -1" specular=".3 .3 .3" mode="track"/>
    	<joint name="root" type="free" damping="0" limited="false"/>
    	<site name="trunk" size=".01" rgba="0 0 0 0"/>
    	<geom name="head" type="ellipsoid" pos="0 0 0" size="0.005 0.005 0.005" material="effector"/>
    	<geom name="trunk" type="box" pos="0 0 0" size="0.08 0.015 0.015"/>
    	<camera name="eye" pos="0 0.04 0" xyaxes="1 0 0 0 0 1"/>
    	<body name="lobe_L" pos="0.08 0 0">
    		<joint name="lobe_L_roll" axis="0 1 0"/>
    		<joint name="lobe_L_yaw" axis="0 0 1"/>
    		<geom name="lobe_L" type="box" size="0.015 0.09 0.09"/>
    	</body>
    	<body name="lobe_R" pos="-0.08 0 0">
    		<joint name="lobe_R_roll" axis="0 1 0"/>
    		<joint name="lobe_R_yaw" axis="0 0 1"/>
    		<geom name="lobe_R" type="box" size="0.015 0.09 0.09"/>
    	</body>
    </body>
  </worldbody>

  <actuator>
  	<position name="lobe_L_roll" joint="lobe_L_roll" ctrlrange="-1 1" kp="5e-4"/>
		<position name="lobe_L_yaw" joint="lobe_L_yaw" ctrlrange="-1 1" kp="5e-4"/>
  	<position name="lobe_R_roll" joint="lobe_R_roll" ctrlrange="-1 1" kp="5e-4"/>
  	<position name="lobe_R_yaw" joint="lobe_R_yaw" ctrlrange="-1 1" kp="5e-4"/>
  </actuator>

  <sensor>
  	<velocimeter name="velocimeter" site="trunk"/>
  	<gyro name="gyro" site="trunk"/>
  </sensor>
</mujoco>